log/output_500_2022_GRU_gpu5.log
wandb: Currently logged in as: pqy000 (pqythu). Use `wandb login --relogin` to force relogin
GPU device ID: 5
newdata/500_2022.npy
0
2024-09-07 16:05:40.555294: I tensorflow/core/platform/cpu_feature_guard.cc:193] This TensorFlow binary is optimized with oneAPI Deep Neural Network Library (oneDNN) to use the following CPU instructions in performance-critical operations:  AVX2 FMA
To enable them in other operations, rebuild TensorFlow with the appropriate compiler flags.
wandb: wandb version 0.17.9 is available!  To upgrade, please run:
wandb:  $ pip install wandb --upgrade
wandb: Tracking run with wandb version 0.12.17
wandb: Run data is saved locally in /home/qingyi/GPU20/DeepLOB/wandb/run-20240907_160533-2coudi0y
wandb: Run `wandb offline` to turn off syncing.
wandb: Syncing run GRU
wandb: ⭐️ View project at https://wandb.ai/pqythu/futures500
wandb: 🚀 View run at https://wandb.ai/pqythu/futures500/runs/2coudi0y
2024-09-07 16:05:41.644989: W tensorflow/compiler/xla/stream_executor/platform/default/dso_loader.cc:64] Could not load dynamic library 'libnvinfer.so.7'; dlerror: libnvinfer.so.7: cannot open shared object file: No such file or directory; LD_LIBRARY_PATH: /opt/cudnn/lib64:/usr/local/cuda/lib64
2024-09-07 16:05:41.645099: W tensorflow/compiler/xla/stream_executor/platform/default/dso_loader.cc:64] Could not load dynamic library 'libnvinfer_plugin.so.7'; dlerror: libnvinfer_plugin.so.7: cannot open shared object file: No such file or directory; LD_LIBRARY_PATH: /opt/cudnn/lib64:/usr/local/cuda/lib64
2024-09-07 16:05:41.645111: W tensorflow/compiler/tf2tensorrt/utils/py_utils.cc:38] TF-TRT Warning: Cannot dlopen some TensorRT libraries. If you would like to use Nvidia GPU with TensorRT, please make sure the missing libraries mentioned above are installed properly.
Model(
  (rnn): LSTM(10, 64, batch_first=True)
  (fc): Linear(in_features=64, out_features=5, bias=True)
)
number of parameters: 19781
Training start
epoch  1 | time used:  1.20s | train_loss 1.497 | valid loss 1.359 | valid acc 0.350 | mae 1.645 | mse 4.865 | rmse 2.21 | r2 -1.25 | sharp -0.17
epoch  2 | time used:  0.05s | train_loss 1.462 | valid loss 1.359 | valid acc 0.350 | mae 1.645 | mse 4.865 | rmse 2.21 | r2 -1.25 | sharp -0.17
epoch  3 | time used:  0.14s | train_loss 1.463 | valid loss 1.359 | valid acc 0.350 | mae 1.645 | mse 4.865 | rmse 2.21 | r2 -1.25 | sharp -0.17
epoch  4 | time used:  0.11s | train_loss 1.450 | valid loss 1.359 | valid acc 0.350 | mae 1.645 | mse 4.865 | rmse 2.21 | r2 -1.25 | sharp -0.17
epoch  5 | time used:  0.06s | train_loss 1.482 | valid loss 1.362 | valid acc 0.350 | mae 1.645 | mse 4.865 | rmse 2.21 | r2 -1.25 | sharp -0.17
epoch  6 | time used:  0.05s | train_loss 1.486 | valid loss 1.424 | valid acc 0.350 | mae 1.645 | mse 4.865 | rmse 2.21 | r2 -1.25 | sharp -0.17
epoch  7 | time used:  0.05s | train_loss 1.510 | valid loss 1.359 | valid acc 0.350 | mae 1.645 | mse 4.865 | rmse 2.21 | r2 -1.25 | sharp -0.17
epoch  8 | time used:  0.04s | train_loss 1.497 | valid loss 1.715 | valid acc 0.165 | mae 2.355 | mse 7.705 | rmse 2.78 | r2 -2.57 | sharp 0.00
epoch  9 | time used:  0.05s | train_loss 1.734 | valid loss 1.818 | valid acc 0.105 | mae 1.345 | mse 2.575 | rmse 1.60 | r2 -0.19 | sharp -0.17
epoch 10 | time used:  0.04s | train_loss 1.603 | valid loss 1.715 | valid acc 0.165 | mae 2.355 | mse 7.705 | rmse 2.78 | r2 -2.57 | sharp 0.00
saving the model to ./save/2022_500/GRU/checkpoint10.pt
epoch 11 | time used:  0.05s | train_loss 1.573 | valid loss 1.371 | valid acc 0.350 | mae 1.645 | mse 4.865 | rmse 2.21 | r2 -1.25 | sharp -0.17
epoch 12 | time used:  0.05s | train_loss 1.461 | valid loss 1.359 | valid acc 0.350 | mae 1.645 | mse 4.865 | rmse 2.21 | r2 -1.25 | sharp -0.17
epoch 13 | time used:  0.04s | train_loss 1.507 | valid loss 1.371 | valid acc 0.350 | mae 1.645 | mse 4.865 | rmse 2.21 | r2 -1.25 | sharp -0.17
epoch 14 | time used:  0.05s | train_loss 1.507 | valid loss 1.359 | valid acc 0.350 | mae 1.645 | mse 4.865 | rmse 2.21 | r2 -1.25 | sharp -0.17
epoch 15 | time used:  0.04s | train_loss 1.473 | valid loss 1.715 | valid acc 0.165 | mae 2.355 | mse 7.705 | rmse 2.78 | r2 -2.57 | sharp 0.00
epoch 16 | time used:  0.04s | train_loss 1.583 | valid loss 1.709 | valid acc 0.165 | mae 2.355 | mse 7.705 | rmse 2.78 | r2 -2.57 | sharp 0.00
epoch 17 | time used:  0.05s | train_loss 1.475 | valid loss 1.371 | valid acc 0.350 | mae 1.645 | mse 4.865 | rmse 2.21 | r2 -1.25 | sharp -0.17
epoch 18 | time used:  0.05s | train_loss 1.491 | valid loss 1.458 | valid acc 0.350 | mae 1.645 | mse 4.865 | rmse 2.21 | r2 -1.25 | sharp -0.17
epoch 19 | time used:  0.04s | train_loss 1.459 | valid loss 1.660 | valid acc 0.165 | mae 2.355 | mse 7.705 | rmse 2.78 | r2 -2.57 | sharp 0.00
epoch 20 | time used:  0.04s | train_loss 1.491 | valid loss 1.359 | valid acc 0.350 | mae 1.645 | mse 4.865 | rmse 2.21 | r2 -1.25 | sharp -0.17
saving the model to ./save/2022_500/GRU/checkpoint20.pt
epoch 21 | time used:  0.04s | train_loss 1.483 | valid loss 1.359 | valid acc 0.350 | mae 1.645 | mse 4.865 | rmse 2.21 | r2 -1.25 | sharp -0.17
epoch 22 | time used:  0.04s | train_loss 1.480 | valid loss 1.359 | valid acc 0.350 | mae 1.645 | mse 4.865 | rmse 2.21 | r2 -1.25 | sharp -0.17
epoch 23 | time used:  0.05s | train_loss 1.462 | valid loss 1.360 | valid acc 0.350 | mae 1.645 | mse 4.865 | rmse 2.21 | r2 -1.25 | sharp -0.17
epoch 24 | time used:  0.04s | train_loss 1.507 | valid loss 1.576 | valid acc 0.350 | mae 1.645 | mse 4.865 | rmse 2.21 | r2 -1.25 | sharp -0.17
epoch 25 | time used:  0.04s | train_loss 1.503 | valid loss 1.359 | valid acc 0.350 | mae 1.645 | mse 4.865 | rmse 2.21 | r2 -1.25 | sharp -0.17
epoch 26 | time used:  0.05s | train_loss 1.483 | valid loss 1.372 | valid acc 0.350 | mae 1.645 | mse 4.865 | rmse 2.21 | r2 -1.25 | sharp -0.17
epoch 27 | time used:  0.05s | train_loss 1.492 | valid loss 1.360 | valid acc 0.350 | mae 1.645 | mse 4.865 | rmse 2.21 | r2 -1.25 | sharp -0.17
epoch 28 | time used:  0.05s | train_loss 1.483 | valid loss 1.678 | valid acc 0.165 | mae 2.355 | mse 7.705 | rmse 2.78 | r2 -2.57 | sharp 0.00
epoch 29 | time used:  0.06s | train_loss 1.568 | valid loss 1.715 | valid acc 0.165 | mae 2.355 | mse 7.705 | rmse 2.78 | r2 -2.57 | sharp 0.00
epoch 30 | time used:  0.06s | train_loss 1.596 | valid loss 1.715 | valid acc 0.165 | mae 2.355 | mse 7.705 | rmse 2.78 | r2 -2.57 | sharp 0.00
saving the model to ./save/2022_500/GRU/checkpoint30.pt
epoch 31 | time used:  0.05s | train_loss 1.584 | valid loss 1.431 | valid acc 0.350 | mae 1.645 | mse 4.865 | rmse 2.21 | r2 -1.25 | sharp -0.17
epoch 32 | time used:  0.04s | train_loss 1.479 | valid loss 1.359 | valid acc 0.350 | mae 1.645 | mse 4.865 | rmse 2.21 | r2 -1.25 | sharp -0.17
epoch 33 | time used:  0.04s | train_loss 1.545 | valid loss 1.715 | valid acc 0.165 | mae 2.355 | mse 7.705 | rmse 2.78 | r2 -2.57 | sharp 0.00
epoch 34 | time used:  0.04s | train_loss 1.496 | valid loss 1.359 | valid acc 0.350 | mae 1.645 | mse 4.865 | rmse 2.21 | r2 -1.25 | sharp -0.17
epoch 35 | time used:  0.05s | train_loss 1.516 | valid loss 1.359 | valid acc 0.350 | mae 1.645 | mse 4.865 | rmse 2.21 | r2 -1.25 | sharp -0.17
epoch 36 | time used:  0.05s | train_loss 1.458 | valid loss 1.359 | valid acc 0.350 | mae 1.645 | mse 4.865 | rmse 2.21 | r2 -1.25 | sharp -0.17
epoch 37 | time used:  0.04s | train_loss 1.471 | valid loss 1.359 | valid acc 0.350 | mae 1.645 | mse 4.865 | rmse 2.21 | r2 -1.25 | sharp -0.17
epoch 38 | time used:  0.04s | train_loss 1.498 | valid loss 1.707 | valid acc 0.165 | mae 2.355 | mse 7.705 | rmse 2.78 | r2 -2.57 | sharp 0.00
epoch 39 | time used:  0.04s | train_loss 1.565 | valid loss 1.715 | valid acc 0.165 | mae 2.355 | mse 7.705 | rmse 2.78 | r2 -2.57 | sharp 0.00
epoch 40 | time used:  0.05s | train_loss 1.492 | valid loss 1.359 | valid acc 0.350 | mae 1.645 | mse 4.865 | rmse 2.21 | r2 -1.25 | sharp -0.17
saving the model to ./save/2022_500/GRU/checkpoint40.pt
